Workbook
Name Nom_Société: 'Desgagné TRIM 2'!$B$2
Name Nom_Société: 'Desgagné 1'!$B$2
Name OLE_LINK4: Données!#REF!
Name TitreColonne1: [1]!Facture[[#Headers],[Quantité]]
Name TitreColonne1: [2]!Facture[[#Headers],[Quantité]]
Name TitreColonne1: [2]!Facture[[#Headers],[Quantité]]
Name TitreColonne1: [3]!Facture[[#Headers],[Quantité]]
Name TitreColonne1: [1]!Facture[[#Headers],[Quantité]]
Name TitreColonne1: [2]!Facture[[#Headers],[Quantité]]
Name TitreColonne1: [3]!Facture[[#Headers],[Quantité]]
Name TitreColonne1: [2]!Facture[[#Headers],[Quantité]]
Name TitreColonne1: [4]!Facture[[#Headers],[Quantité]]
Name ZoneTitreColonne1..E13.1: 'Desgagné TRIM 2'!$B$12
Name ZoneTitreColonne1..E13.1: 'Desgagné 1'!$B$12
Name ZoneTitreLigne1..E5: 'Desgagné TRIM 2'!$D$3
Name ZoneTitreLigne1..E5: 'Desgagné 1'!$D$3

Sheet Données
A1: ISSA OUEDRAOGO
B4: Produits | C4: Dimension unitaire | D4: La | E4: Lo | F4: Ha | G4: Dimension en mètre cube | H4: Coûts unitaires (+15% «express») | I4: Prix de vente unitaire | J4: Lots | K4: Demande max. | L4: Demande min. | M4: Projection de ventes trim 1 | N4: Projection Mois 1
B6: P1 | C6: 1x0,4x0,45 m | D6: 1 | E6: 0.4 | F6: 0.45 | G6: =D6*E6*F6 -> 0.18 | H6: 6.75 | I6: 10.87 | J6: 50 | K6: 5390 | L6: 5080 | M6: =AVERAGE(K6:L6) -> 5235 | N6: =M6*Données!$F$26 -> 1555.7207
B7: P2 | C7: 0,5x0,5x0,9 m | D7: 0.5 | E7: 0.5 | F7: 0.9 | G7: =D7*E7*F7 -> 0.225 | H7: 13.5 | I7: 21.74 | J7: 100 | K7: 6290 | L7: 5980 | M7: =AVERAGE(K7:L7) -> 6135 | N7: =M7*Données!$F$26 -> 1823.1798
A8: Trim 1 et trim 4 | B8: P3 | C8: 0,9x0,5x1½ m | D8: 0.9 | E8: 0.5 | F8: 1.5 | G8: =D8*E8*F8 -> 0.675 | H8: 20 | I8: 35.02 | J8: 100 | K8: 3880 | L8: 3370 | M8: =AVERAGE(K8:L8) -> 3625 | N8: =M8*Données!$F$26 -> 1077.266 | AI8: =$AD8*(1+AI$5) -> 0 | AJ8: =$AD8*1+(AJ$5) -> 0 | AK8: =$AD8*1+(AK$5) -> 0 | AL8: =$AD8*1+(AL$5) -> 0 | AM8: =$AD8*1+(AM$5) -> 0 | AN8: =$AD8*1+(AN$5) -> 0 | AO8: =$AD8*1+(AO$5) -> 0 | AP8: =$AD8*1+(AP$5) -> 0 | AQ8: =$AD8*1+(AQ$5) -> 0 | ... AT8: =$AD8*1+(AT$5) -> 0 | AU8: =SUM(AI8:AT8) -> 0
B9: P4 | C9: 1x0,5x1 m | D9: 1 | E9: 0.5 | F9: 1 | G9: =D9*E9*F9 -> 0.5 | H9: 29 | I9: 42.26 | J9: 100 | K9: 2960 | L9: 2760 | M9: =AVERAGE(K9:L9) -> 2860 | N9: =M9*Données!$F$26 -> 849.92571 | AI9: =$N9*(1+AI$5) -> 849.92571 | AJ9: =$N9*(1+AJ$5) -> 849.92571 | AK9: =$N9*(1+AK$5) -> 849.92571 | AL9: =$N9*(1+AL$5) -> 849.92571 | AM9: =$N9*(1+AM$5) -> 849.92571 | AN9: =$N9*(1+AN$5) -> 849.92571 | AO9: =$N9*(1+AO$5) -> 849.92571 | AP9: =$N9*(1+AP$5) -> 849.92571 | ... AT9: =$N9*(1+AT$5) -> 849.92571 | AU9: =SUM(AI9:AT9) -> 10199.108
B10: P5 | C10: 0,5x1x1½ m | D10: 0.5 | E10: 1 | F10: 1.5 | G10: =D10*E10*F10 -> 0.75 | H10: 35 | I10: 59.17 | J10: 50 | K10: 4800 | L10: 4700 | M10: =AVERAGE(K10:L10) -> 4750 | N10: =M10*Données!$F$26 -> 1411.5899 | AU10: =SUM(AI10:AT10) -> 0
A11: Trim 1 et trim 4 | B11: P6 | C11: 0,5x1x1,8 m | D11: 0.5 | E11: 1 | F11: 1.8 | G11: =D11*E11*F11 -> 0.9 | H11: 42 | I11: 64 | J11: 100 | K11: 1690 | L11: 1590 | M11: =AVERAGE(K11:L11) -> 1640 | N11: =M11*Données!$F$26 -> 487.36999 | AI11: =$N11*(1+AI$5) -> 487.36999 | AJ11: =$N11*(1+AJ$5) -> 487.36999 | AK11: =$N11*(1+AK$5) -> 487.36999 | AL11: =$N11*(1+AL$5) -> 487.36999 | AM11: =$N11*(1+AM$5) -> 487.36999 | AN11: =$N11*(1+AN$5) -> 487.36999 | AO11: =$N11*(1+AO$5) -> 487.36999 | AP11: =$N11*(1+AP$5) -> 487.36999 | ... AT11: =$N11*(1+AT$5) -> 487.36999 | AU11: =SUM(AI11:AT11) -> 5848.4398
B12: P7 | C12: 0,5x1x1¾ m | D12: 0.5 | E12: 1 | F12: 1.75 | G12: =D12*E12*F12 -> 0.875 | H12: 54 | I12: 82.11 | J12: 50 | K12: 2480 | L12: 2430 | M12: =AVERAGE(K12:L12) -> 2455 | N12: =M12*Données!$F$26 -> 729.56909 | AI12: =$N12*(1+AI$5) -> 729.56909 | AJ12: =$N12*(1+AJ$5) -> 729.56909 | AK12: =$N12*(1+AK$5) -> 729.56909 | AL12: =$N12*(1+AL$5) -> 729.56909 | AM12: =$N12*(1+AM$5) -> 729.56909 | AN12: =$N12*(1+AN$5) -> 729.56909 | AO12: =$N12*(1+AO$5) -> 729.56909 | AP12: =$N12*(1+AP$5) -> 729.56909 | ... AT12: =$N12*(1+AT$5) -> 729.56909 | AU12: =SUM(AI12:AT12) -> 8754.8291
B13: P8 | C13: 1,8x1x1 m | D13: 1.8 | E13: 1 | F13: 1 | G13: =D13*E13*F13 -> 1.8 | H13: 59 | I13: 85.73 | J13: 10 | K13: 7530 | L13: 7490 | M13: =AVERAGE(K13:L13) -> 7510 | N13: =M13*Données!$F$26 -> 2231.7979 | AU13: =SUM(AI13:AT13) -> 0
A14: Trim 1 et trim 4 | B14: P9 | C14: 0,9x0,5x1¼ m | D14: 0.9 | E14: 0.5 | F14: 1.25 | G14: =D14*E14*F14 -> 0.5625 | H14: 66 | I14: 108.68 | J14: 10 | K14: 4290 | L14: 4260 | M14: =AVERAGE(K14:L14) -> 4275 | N14: =M14*Données!$F$26 -> 1270.4309 | AI14: =$N14*(1+AI$5) -> 1270.4309 | AJ14: =$N14*(1+AJ$5) -> 1270.4309 | AK14: =$N14*(1+AK$5) -> 1270.4309 | AL14: =$N14*(1+AL$5) -> 1270.4309 | AM14: =$N14*(1+AM$5) -> 1270.4309 | AN14: =$N14*(1+AN$5) -> 1270.4309 | AO14: =$N14*(1+AO$5) -> 1270.4309 | AP14: =$N14*(1+AP$5) -> 1270.4309 | ... AT14: =$N14*(1+AT$5) -> 1270.4309 | AU14: =SUM(AI14:AT14) -> 15245.171
B15: P10 | C15: 1x0,5x1½ m | D15: 1 | E15: 0.5 | F15: 1.5 | G15: =D15*E15*F15 -> 0.75 | H15: 69 | I15: 107.47 | J15: 10 | K15: 1130 | L15: 1120 | M15: =AVERAGE(K15:L15) -> 1125 | N15: =M15*Données!$F$26 -> 334.32392 | AI15: =$N15*(1+AI$5) -> 334.32392 | AJ15: =$N15*(1+AJ$5) -> 334.32392 | AK15: =$N15*(1+AK$5) -> 334.32392 | AL15: =$N15*(1+AL$5) -> 334.32392 | AM15: =$N15*(1+AM$5) -> 334.32392 | AN15: =$N15*(1+AN$5) -> 334.32392 | AO15: =$N15*(1+AO$5) -> 334.32392 | AP15: =$N15*(1+AP$5) -> 334.32392 | ... AT15: =$N15*(1+AT$5) -> 334.32392 | AU15: =SUM(AI15:AT15) -> 4011.8871
A16: Trim 1 et trim 4 | B16: P11 | C16: 0,5x0,9x1½ m | D16: 0.5 | E16: 0.9 | F16: 1.5 | G16: =D16*E16*F16 -> 0.675 | H16: 22 | I16: 36.23 | J16: 100 | K16: 920 | L16: 820 | M16: =AVERAGE(K16:L16) -> 870 | N16: =M16*Données!$F$26 -> 258.54383 | AU16: =SUM(AI16:AT16) -> 0
A17: Trim 2 et trim 4 | B17: P12 | C17: 1x1¾x1 m | D17: 1 | E17: 1.75 | F17: 1 | G17: =D17*E17*F17 -> 1.75 | H17: 43 | I17: 63.4 | J17: 10 | K17: 2660 | L17: 2530 | M17: =AVERAGE(K17:L17) -> 2595 | N17: =M17*Données!$F$26 -> 771.17385 | AI17: =$N17*(1+AI$5) -> 771.17385 | AJ17: =$N17*(1+AJ$5) -> 771.17385 | AK17: =$N17*(1+AK$5) -> 771.17385 | AL17: =$N17*(1+AL$5) -> 771.17385 | AM17: =$N17*(1+AM$5) -> 771.17385 | AN17: =$N17*(1+AN$5) -> 771.17385 | AO17: =$N17*(1+AO$5) -> 771.17385 | AP17: =$N17*(1+AP$5) -> 771.17385 | ... AT17: =$N17*(1+AT$5) -> 771.17385 | AU17: =SUM(AI17:AT17) -> 9254.0862
A18: Trim 2 et trim 4 | B18: P13 | C18: 1x1x1¼ m | D18: 1 | E18: 1 | F18: 1.25 | G18: =D18*E18*F18 -> 1.25 | H18: 65 | I18: 99.62 | J18: 10 | K18: 1080 | L18: 1020 | M18: =AVERAGE(K18:L18) -> 1050 | N18: =M18*Données!$F$26 -> 312.03566 | AU18: =SUM(AI18:AT18) -> 0
AU19: =SUM(AI19:AT19) -> 0
AU20: =SUM(AI20:AT20) -> 0
D21: 0.1 | E21: 0.15 | AE21: =SUM(AE8:AE20) -> 0 | AI21: =SUM(AI8:AI20) -> 4442.7935 | AJ21: =SUM(AJ8:AJ20) -> 4442.7935 | AK21: =SUM(AK8:AK20) -> 4442.7935 | AL21: =SUM(AL8:AL20) -> 4442.7935 | AM21: =SUM(AM8:AM20) -> 4442.7935 | AN21: =SUM(AN8:AN20) -> 4442.7935 | AO21: =SUM(AO8:AO20) -> 4442.7935 | AP21: =SUM(AP8:AP20) -> 4442.7935 | ... AU21: =SUM(AU8:AU20) -> 53313.522
C22: Mois 1 | D22: Mois 2 | E22: Mois 3 | F22: trimestre
B23: Valeur | C23: 1 | D23: =C23*(1+D21) -> 1.1 | E23: =(1+E21)*D23 -> 1.265 | F23: =SUM(C23:E23) -> 3.365 | G23: =1 + 1.2 + 1.44 -> 3.64
C24: =C8*$A24 -> #VALUE! | O24: =SUM(C24:N24) -> #VALUE! | S24: =$Q24*S8 -> 0 | AE24: =SUM(S24:AD24) -> 0 | AI24: =AI8*$AG24 -> 0 | AJ24: =AJ8*$AG24 -> 0 | AK24: =AK8*$AG24 -> 0 | AL24: =AL8*$AG24 -> 0 | AM24: =AM8*$AG24 -> 0 | AN24: =AN8*$AG24 -> 0 | AO24: =AO8*$AG24 -> 0 | AP24: =AP8*$AG24 -> 0 | ... AT24: =AT8*$AG24 -> 0 | AU24: =SUM(AI24:AT24) -> 0
B25: Donc, le rapport entre le mois 1 et le trimestre est de : 1 / 3,64, soit 27,5%. | S25: =$Q25*S9 -> 0 | AE25: =SUM(S25:AD25) -> 0 | AI25: =AI9*$AG25 -> 0 | AJ25: =AJ9*$AG25 -> 0 | AK25: =AK9*$AG25 -> 0 | AL25: =AL9*$AG25 -> 0 | AM25: =AM9*$AG25 -> 0 | AN25: =AN9*$AG25 -> 0 | AO25: =AO9*$AG25 -> 0 | AP25: =AP9*$AG25 -> 0 | ... AT25: =AT9*$AG25 -> 0 | AU25: =SUM(AI25:AT25) -> 0
F26: =1/F23 -> 0.29717682 | AE26: =SUM(S26:AD26) -> 0 | AI26: =AI10*$AG26 -> 0 | AJ26: =AJ10*$AG26 -> 0 | AK26: =AK10*$AG26 -> 0 | AL26: =AL10*$AG26 -> 0 | AM26: =AM10*$AG26 -> 0 | AN26: =AN10*$AG26 -> 0 | AO26: =AO10*$AG26 -> 0 | AP26: =AP10*$AG26 -> 0 | ... AT26: =AT10*$AG26 -> 0 | AU26: =SUM(AI26:AT26) -> 0
AE27: =SUM(S27:AD27) -> 0 | AI27: =AI11*$AG27 -> 0 | AJ27: =AJ11*$AG27 -> 0 | AK27: =AK11*$AG27 -> 0 | AL27: =AL11*$AG27 -> 0 | AM27: =AM11*$AG27 -> 0 | AN27: =AN11*$AG27 -> 0 | AO27: =AO11*$AG27 -> 0 | AP27: =AP11*$AG27 -> 0 | ... AT27: =AT11*$AG27 -> 0 | AU27: =SUM(AI27:AT27) -> 0
AE28: =SUM(S28:AD28) -> 0 | AI28: =AI12*$AG28 -> 0 | AJ28: =AJ12*$AG28 -> 0 | AK28: =AK12*$AG28 -> 0 | AL28: =AL12*$AG28 -> 0 | AM28: =AM12*$AG28 -> 0 | AN28: =AN12*$AG28 -> 0 | AO28: =AO12*$AG28 -> 0 | AP28: =AP12*$AG28 -> 0 | ... AT28: =AT12*$AG28 -> 0 | AU28: =SUM(AI28:AT28) -> 0
AE29: =SUM(S29:AD29) -> 0 | AI29: =AI13*$AG29 -> 0 | AJ29: =AJ13*$AG29 -> 0 | AK29: =AK13*$AG29 -> 0 | AL29: =AL13*$AG29 -> 0 | AM29: =AM13*$AG29 -> 0 | AN29: =AN13*$AG29 -> 0 | AO29: =AO13*$AG29 -> 0 | AP29: =AP13*$AG29 -> 0 | ... AT29: =AT13*$AG29 -> 0 | AU29: =SUM(AI29:AT29) -> 0
AE30: =SUM(S30:AD30) -> 0 | AI30: =AI14*$AG30 -> 0 | AJ30: =AJ14*$AG30 -> 0 | AK30: =AK14*$AG30 -> 0 | AL30: =AL14*$AG30 -> 0 | AM30: =AM14*$AG30 -> 0 | AN30: =AN14*$AG30 -> 0 | AO30: =AO14*$AG30 -> 0 | AP30: =AP14*$AG30 -> 0 | ... AT30: =AT14*$AG30 -> 0 | AU30: =SUM(AI30:AT30) -> 0
AE31: =SUM(S31:AD31) -> 0 | AI31: =AI15*$AG31 -> 0 | AJ31: =AJ15*$AG31 -> 0 | AK31: =AK15*$AG31 -> 0 | AL31: =AL15*$AG31 -> 0 | AM31: =AM15*$AG31 -> 0 | AN31: =AN15*$AG31 -> 0 | AO31: =AO15*$AG31 -> 0 | AP31: =AP15*$AG31 -> 0 | ... AT31: =AT15*$AG31 -> 0 | AU31: =SUM(AI31:AT31) -> 0
AE32: =SUM(S32:AD32) -> 0 | AI32: =AI16*$AG32 -> 0 | AJ32: =AJ16*$AG32 -> 0 | AK32: =AK16*$AG32 -> 0 | AL32: =AL16*$AG32 -> 0 | AM32: =AM16*$AG32 -> 0 | AN32: =AN16*$AG32 -> 0 | AO32: =AO16*$AG32 -> 0 | AP32: =AP16*$AG32 -> 0 | ... AT32: =AT16*$AG32 -> 0 | AU32: =SUM(AI32:AT32) -> 0
S33: =$Q33*S17 -> 0 | AE33: =SUM(S33:AD33) -> 0 | AI33: =AI17*$AG33 -> 0 | AJ33: =AJ17*$AG33 -> 0 | AK33: =AK17*$AG33 -> 0 | AL33: =AL17*$AG33 -> 0 | AM33: =AM17*$AG33 -> 0 | AN33: =AN17*$AG33 -> 0 | AO33: =AO17*$AG33 -> 0 | AP33: =AP17*$AG33 -> 0 | ... AT33: =AT17*$AG33 -> 0 | AU33: =SUM(AI33:AT33) -> 0
S34: =$Q34*S18 -> 0 | AE34: =SUM(S34:AD34) -> 0 | AI34: =AI18*$AG34 -> 0 | AJ34: =AJ18*$AG34 -> 0 | AK34: =AK18*$AG34 -> 0 | AL34: =AL18*$AG34 -> 0 | AM34: =AM18*$AG34 -> 0 | AN34: =AN18*$AG34 -> 0 | AO34: =AO18*$AG34 -> 0 | AP34: =AP18*$AG34 -> 0 | ... AT34: =AT18*$AG34 -> 0 | AU34: =SUM(AI34:AT34) -> 0
AE35: =SUM(S35:AD35) -> 0 | AI35: =AI19*$AG35 -> 0 | AJ35: =AJ19*$AG35 -> 0 | AK35: =AK19*$AG35 -> 0 | AL35: =AL19*$AG35 -> 0 | AM35: =AM19*$AG35 -> 0 | AN35: =AN19*$AG35 -> 0 | AO35: =AO19*$AG35 -> 0 | AP35: =AP19*$AG35 -> 0 | ... AT35: =AT19*$AG35 -> 0 | AU35: =SUM(AI35:AT35) -> 0
AE36: =SUM(S36:AD36) -> 0 | AI36: =AI20*$AG36 -> 0 | AJ36: =AJ20*$AG36 -> 0 | AK36: =AK20*$AG36 -> 0 | AL36: =AL20*$AG36 -> 0 | AM36: =AM20*$AG36 -> 0 | AN36: =AN20*$AG36 -> 0 | AO36: =AO20*$AG36 -> 0 | AP36: =AP20*$AG36 -> 0 | ... AT36: =AT20*$AG36 -> 0 | AU36: =SUM(AI36:AT36) -> 0
S37: =SUM(S24:S36) -> 0 | T37: =SUM(T24:T36) -> 0 | U37: =SUM(U24:U36) -> 0 | V37: =SUM(V24:V36) -> 0 | W37: =SUM(W24:W36) -> 0 | X37: =SUM(X24:X36) -> 0 | Y37: =SUM(Y24:Y36) -> 0 | Z37: =SUM(Z24:Z36) -> 0 | ... AE37: =SUM(AE24:AE36) -> 0 | AI37: =SUM(AI24:AI36) -> 0 | AJ37: =SUM(AJ24:AJ36) -> 0 | AK37: =SUM(AK24:AK36) -> 0 | AL37: =SUM(AL24:AL36) -> 0 | AM37: =SUM(AM24:AM36) -> 0 | AN37: =SUM(AN24:AN36) -> 0 | AO37: =SUM(AO24:AO36) -> 0 | AP37: =SUM(AP24:AP36) -> 0 | ... AU37: =SUM(AU24:AU36) -> 0
B40: Année 1 | C40: Année 2 | D40: Année 3
A41: Trimestre 1 | B41: =SUM(C21+D21+E21) -> 0.25 | C41: =SUM(S21:U21) -> 0 | D41: =SUM(AI21:AK21) -> 13328.38
A42: Trimestre 2 | B42: =SUM(E21+F21+G21) -> 0.15 | C42: =SUM(V21:X21) -> 0 | D42: =SUM(AL21:AN21) -> 13328.38
A43: Trimestre 3 | B43: =SUM(I21+J21+K21) -> 0 | C43: =SUM(Y21:AA21) -> 0 | D43: =SUM(AO21:AQ21) -> 13328.38
A44: Trimestre 4 | B44: =SUM(L21:N21) -> 0 | C44: =SUM(AB21:AD21) -> 0 | D44: =SUM(AR21:AT21) -> 13328.38

Sheet S1 - projections
A1: ISSA OUEDRAOGO
A3: Prévision ventes année 1 : | Q3: Prévision ventes année 2 : | AG3: Prévision ventes année 3 :
C4: TRIM 1 | F4: TRIM 2 | I4: TRIM 3 | L4: TRIM 4 | S4: TRIM 1 | V4: TRIM 2 | Y4: TRIM 3 | AB4: TRIM 4 | AI4: TRIM 1 | AL4: TRIM 2 | AO4: TRIM 3 | AR4: TRIM 4
B5: Augmentations : | D5: 0.1 | E5: 0.15 | F5: 0.15 | G5: 0.15 | H5: 0.1 | I5: 0.1 | J5: 0.05 | K5: 0.05 | L5: 0.05 | M5: 0 | N5: 0 | R5: Augmentations : | S5: 0 | T5: 0 | U5: 0 | V5: 0 | W5: 0 | X5: 0 | Y5: 0 | Z5: 0 | AA5: 0 | AB5: 0 | AC5: 0 | AD5: 0 | AH5: Augmentations : | AI5: 0 | AJ5: 0 | AK5: 0 | AL5: 0 | AM5: 0 | AN5: 0 | AO5: 0 | AP5: 0 | AQ5: 0 | AR5: 0 | AS5: 0 | AT5: 0
C6: Mois 1 | D6: Mois 2 | E6: Mois 3 | F6: Mois 4 | G6: Mois 5 | H6: Mois 6 | I6: Mois 7 | J6: Mois 8 | K6: Mois 9 | L6: Mois 10 | M6: Mois 11 | N6: Mois 12 | O6: Année 1 | S6: Mois 1 | T6: Mois 2 | U6: Mois 3 | V6: Mois 4 | W6: Mois 5 | X6: Mois 6 | Y6: Mois 7 | Z6: Mois 8 | AA6: Mois 9 | AB6: Mois 10 | AC6: Mois 11 | AD6: Mois 12 | AE6: Année 2 | AI6: Mois 1 | AJ6: Mois 2 | AK6: Mois 3 | AL6: Mois 4 | AM6: Mois 5 | AN6: Mois 6 | AO6: Mois 7 | AP6: Mois 8 | AQ6: Mois 9 | AR6: Mois 10 | AS6: Mois 11 | AT6: Mois 12 | AU6: Année 3
A7: Quantité : | B7: Produits | Q7: Quantité : | R7: Produits | AG7: Quantité : | AH7: Produits
B8: P1 | C8: =Données!N6 -> 1555.7207 | D8: =C8*(1+D$5) -> 1711.2927 | E8: =D8*(1+E$5) -> 1967.9866 | F8: =E8*(1+F$5) -> 2263.1846 | G8: =F8*(1+G$5) -> 2602.6623 | H8: =G8*(1+H$5) -> 2862.9285 | I8: =H8*(1+I$5) -> 3149.2214 | J8: =I8*(1+J$5) -> 3306.6825 | K8: =J8*(1+K$5) -> 3472.0166 | ... N8: =M8*(1+N$5) -> 3645.6174 | O8: =SUM(C8:N8) -> 33828.548 | R8: P1 | S8: =$N8*(1+$T5) -> 3645.6174 | T8: =$N8*(1+$T5) -> 3645.6174 | U8: =$N8*(1+$T5) -> 3645.6174 | V8: =$N8*(1+$T5) -> 3645.6174 | W8: =$N8*(1+$T5) -> 3645.6174 | X8: =$N8*(1+$T5) -> 3645.6174 | Y8: =$N8*(1+$T5) -> 3645.6174 | Z8: =$N8*(1+$T5) -> 3645.6174 | ... AD8: =$N8*(1+$T5) -> 3645.6174 | AE8: =SUM(S8:AD8) -> 43747.409 | AH8: P1 | AI8: =$AD8*(1+AI$5) -> 3645.6174 | AJ8: =$AD8*1+(AJ$5) -> 3645.6174 | AK8: =$AD8*1+(AK$5) -> 3645.6174 | AL8: =$AD8*1+(AL$5) -> 3645.6174 | AM8: =$AD8*1+(AM$5) -> 3645.6174 | AN8: =$AD8*1+(AN$5) -> 3645.6174 | AO8: =$AD8*1+(AO$5) -> 3645.6174 | AP8: =$AD8*1+(AP$5) -> 3645.6174 | AQ8: =$AD8*1+(AQ$5) -> 3645.6174 | ... AT8: =$AD8*1+(AT$5) -> 3645.6174 | AU8: =SUM(AI8:AT8) -> 43747.409
B9: P2 | C9: =Données!N7 -> 1823.1798 | D9: =C9*(1+D$5) -> 2005.4978 | E9: =D9*(1+E$5) -> 2306.3224 | F9: =E9*(1+F$5) -> 2652.2708 | G9: =F9*(1+G$5) -> 3050.1114 | H9: =G9*(1+H$5) -> 3355.1226 | I9: =H9*(1+I$5) -> 3690.6348 | J9: =I9*(1+J$5) -> 3875.1666 | K9: =J9*(1+K$5) -> 4068.9249 | ... N9: =M9*(1+N$5) -> 4272.3711 | O9: =SUM(C9:N9) -> 39644.344 | R9: P2 | S9: =$N9*(1+T$5) -> 4272.3711 | T9: =$N9*(1+U$5) -> 4272.3711 | U9: =$N9*(1+V$5) -> 4272.3711 | V9: =$N9*(1+W$5) -> 4272.3711 | W9: =$N9*(1+X$5) -> 4272.3711 | X9: =$N9*(1+Y$5) -> 4272.3711 | Y9: =$N9*(1+Z$5) -> 4272.3711 | Z9: =$N9*(1+AA$5) -> 4272.3711 | ... AD9: =$N9*(1+AE$5) -> 4272.3711 | AE9: =SUM(S9:AD9) -> 51268.454 | AH9: P2 | AI9: =$N9*(1+AI$5) -> 4272.3711 | AJ9: =$N9*(1+AJ$5) -> 4272.3711 | AK9: =$N9*(1+AK$5) -> 4272.3711 | AL9: =$N9*(1+AL$5) -> 4272.3711 | AM9: =$N9*(1+AM$5) -> 4272.3711 | AN9: =$N9*(1+AN$5) -> 4272.3711 | AO9: =$N9*(1+AO$5) -> 4272.3711 | AP9: =$N9*(1+AP$5) -> 4272.3711 | ... AT9: =$N9*(1+AT$5) -> 4272.3711 | AU9: =SUM(AI9:AT9) -> 51268.454
A10: (Trim 1 et 4 seulement) | B10: P3 | C10: =Données!N8 -> 1077.266 | D10: =C10*(1+D$5) -> 1184.9926 | E10: =D10*(1+E$5) -> 1362.7415 | L10: =E10*(1+F$5) -> 1567.1527 | M10: =L10*(1+G$5) -> 1802.2256 | N10: =M10*(1+H$5) -> 1982.4481 | O10: =SUM(C10:N10) -> 8976.8264 | R10: P3 | S10: =1077.26597325409*1+(I$5) -> 1077.366 | T10: =1184.99257057949*1+(J$5) -> 1185.0426 | U10: =1362.74145616642*1+(L$5) -> 1362.7915 | AB10: =2524.42467241654*1+(T$5) -> 2524.4247 | AC10: =2524.42467241654*1+(U$5) -> 2524.4247 | AD10: =2524.42467241654*1+(V$5) -> 2524.4247 | AE10: =SUM(S10:AD10) -> 11198.474 | AH10: P3 | AI10: =1077.26597325409*1+(W$5) -> 1077.266 | AJ10: =1077.26597325409*1+(X$5) -> 1077.266 | AK10: =1077.26597325409*1+(Y$5) -> 1077.266 | AR10: =2524.42467241654*1+(AC$5) -> 2524.4247 | AS10: =2524.42467241654*1+(AD$5) -> 2524.4247 | AT10: =2524.42467241654*1+(AE$5) -> 2524.4247 | AU10: =SUM(AI10:AT10) -> 10805.072
B11: P4 | C11: =Données!N9 -> 849.92571 | D11: =C11*(1+D$5) -> 934.91828 | E11: =D11*(1+E$5) -> 1075.156 | F11: =E11*(1+F$5) -> 1236.4294 | G11: =F11*(1+G$5) -> 1421.8938 | H11: =G11*(1+H$5) -> 1564.0832 | I11: =H11*(1+I$5) -> 1720.4915 | J11: =I11*(1+J$5) -> 1806.5161 | K11: =J11*(1+K$5) -> 1896.8419 | ... N11: =M11*(1+N$5) -> 1991.684 | O11: =SUM(C11:N11) -> 18481.308 | R11: P4 | S11: =$N11*(1+T$5) -> 1991.684 | T11: =$N11*(1+U$5) -> 1991.684 | U11: =$N11*(1+V$5) -> 1991.684 | V11: =$N11*(1+W$5) -> 1991.684 | W11: =$N11*(1+X$5) -> 1991.684 | X11: =$N11*(1+Y$5) -> 1991.684 | Y11: =$N11*(1+Z$5) -> 1991.684 | Z11: =$N11*(1+AA$5) -> 1991.684 | ... AD11: =$N11*(1+AE$5) -> 1991.684 | AE11: =SUM(S11:AD11) -> 23900.208 | AH11: P4 | AI11: =$N11*(1+AI$5) -> 1991.684 | AJ11: =$N11*(1+AJ$5) -> 1991.684 | AK11: =$N11*(1+AK$5) -> 1991.684 | AL11: =$N11*(1+AL$5) -> 1991.684 | AM11: =$N11*(1+AM$5) -> 1991.684 | AN11: =$N11*(1+AN$5) -> 1991.684 | AO11: =$N11*(1+AO$5) -> 1991.684 | AP11: =$N11*(1+AP$5) -> 1991.684 | ... AT11: =$N11*(1+AT$5) -> 1991.684 | AU11: =SUM(AI11:AT11) -> 23900.208
B12: P5 | C12: =Données!N10 -> 1411.5899 | D12: =C12*(1+D$5) -> 1552.7489 | E12: =D12*(1+E$5) -> 1785.6612 | F12: =E12*(1+F$5) -> 2053.5104 | G12: =F12*(1+G$5) -> 2361.537 | H12: =G12*(1+H$5) -> 2597.6907 | I12: =H12*(1+I$5) -> 2857.4597 | J12: =I12*(1+J$5) -> 3000.3327 | K12: =J12*(1+K$5) -> 3150.3493 | ... N12: =M12*(1+N$5) -> 3307.8668 | O12: =SUM(C12:N12) -> 30694.48 | R12: P5 | S12: =$N12*(1+T$5) -> 3307.8668 | T12: =$N12*(1+U$5) -> 3307.8668 | U12: =$N12*(1+V$5) -> 3307.8668 | V12: =$N12*(1+W$5) -> 3307.8668 | W12: =$N12*(1+X$5) -> 3307.8668 | X12: =$N12*(1+Y$5) -> 3307.8668 | Y12: =$N12*(1+Z$5) -> 3307.8668 | Z12: =$N12*(1+AA$5) -> 3307.8668 | ... AD12: =$N12*(1+AE$5) -> 3307.8668 | AE12: =SUM(S12:AD12) -> 39694.402 | AH12: P5 | AI12: =$N12*(1+AI$5) -> 3307.8668 | AJ12: =$N12*(1+AJ$5) -> 3307.8668 | AK12: =$N12*(1+AK$5) -> 3307.8668 | AL12: =$N12*(1+AL$5) -> 3307.8668 | AM12: =$N12*(1+AM$5) -> 3307.8668 | AN12: =$N12*(1+AN$5) -> 3307.8668 | AO12: =$N12*(1+AO$5) -> 3307.8668 | AP12: =$N12*(1+AP$5) -> 3307.8668 | ... AT12: =$N12*(1+AT$5) -> 3307.8668 | AU12: =SUM(AI12:AT12) -> 39694.402
A13: (Trim 1 et 4 seulement) | B13: P6 | C13: =Données!N11 -> 487.36999 | D13: =C13*(1+D$5) -> 536.10698 | E13: =D13*(1+E$5) -> 616.52303 | L13: =E13*(1+F$5) -> 709.00149 | M13: =L13*(1+G$5) -> 815.35171 | N13: =M13*(1+H$5) -> 896.88688 | O13: =SUM(C13:N13) -> 4061.2401 | R13: P6 | S13: =487.369985141159*1+(I$5) -> 487.46999 | T13: =536.106983655275*1+(J$5) -> 536.15698 | U13: =616.523031203566*1+(L$5) -> 616.57303 | AB13: =1142.08454145189*1+(T$5) -> 1142.0845 | AC13: =1142.08454145189*1+(U$5) -> 1142.0845 | AD13: =1142.08454145189*1+(V$5) -> 1142.0845 | AE13: =SUM(S13:AD13) -> 5066.4536 | AH13: P6 | AI13: =487.369985141159*1+(W$5) -> 487.36999 | AJ13: =487.369985141159*1+(X$5) -> 487.36999 | AK13: =487.369985141159*1+(Y$5) -> 487.36999 | AR13: =1142.08454145189*1+(AC$5) -> 1142.0845 | AS13: =1142.08454145189*1+(AD$5) -> 1142.0845 | AT13: =1142.08454145189*1+(AE$5) -> 1142.0845 | AU13: =SUM(AI13:AT13) -> 4888.3636
B14: P7 | C14: =Données!N12 -> 729.56909 | D14: =C14*(1+D$5) -> 802.526 | E14: =D14*(1+E$5) -> 922.9049 | F14: =E14*(1+F$5) -> 1061.3406 | G14: =F14*(1+G$5) -> 1220.5417 | H14: =G14*(1+H$5) -> 1342.5959 | I14: =H14*(1+I$5) -> 1476.8555 | J14: =I14*(1+J$5) -> 1550.6983 | K14: =J14*(1+K$5) -> 1628.2332 | ... N14: =M14*(1+N$5) -> 1709.6448 | O14: =SUM(C14:N14) -> 15864.2 | R14: P7 | S14: =$N14*(1+T$5) -> 1709.6448 | T14: =$N14*(1+U$5) -> 1709.6448 | U14: =$N14*(1+V$5) -> 1709.6448 | V14: =$N14*(1+W$5) -> 1709.6448 | W14: =$N14*(1+X$5) -> 1709.6448 | X14: =$N14*(1+Y$5) -> 1709.6448 | Y14: =$N14*(1+Z$5) -> 1709.6448 | Z14: =$N14*(1+AA$5) -> 1709.6448 | ... AD14: =$N14*(1+AE$5) -> 1709.6448 | AE14: =SUM(S14:AD14) -> 20515.738 | AH14: P7 | AI14: =$N14*(1+AI$5) -> 1709.6448 | AJ14: =$N14*(1+AJ$5) -> 1709.6448 | AK14: =$N14*(1+AK$5) -> 1709.6448 | AL14: =$N14*(1+AL$5) -> 1709.6448 | AM14: =$N14*(1+AM$5) -> 1709.6448 | AN14: =$N14*(1+AN$5) -> 1709.6448 | AO14: =$N14*(1+AO$5) -> 1709.6448 | AP14: =$N14*(1+AP$5) -> 1709.6448 | ... AT14: =$N14*(1+AT$5) -> 1709.6448 | AU14: =SUM(AI14:AT14) -> 20515.738
B15: P8 | C15: =Données!N13 -> 2231.7979 | D15: =C15*(1+D$5) -> 2454.9777 | E15: =D15*(1+E$5) -> 2823.2244 | F15: =E15*(1+F$5) -> 3246.708 | G15: =F15*(1+G$5) -> 3733.7142 | H15: =G15*(1+H$5) -> 4107.0857 | I15: =H15*(1+I$5) -> 4517.7942 | J15: =I15*(1+J$5) -> 4743.6839 | K15: =J15*(1+K$5) -> 4980.8681 | ... N15: =M15*(1+N$5) -> 5229.9115 | O15: =SUM(C15:N15) -> 48529.589 | R15: P8 | S15: =$N15*(1+T$5) -> 5229.9115 | T15: =$N15*(1+U$5) -> 5229.9115 | U15: =$N15*(1+V$5) -> 5229.9115 | V15: =$N15*(1+W$5) -> 5229.9115 | W15: =$N15*(1+X$5) -> 5229.9115 | X15: =$N15*(1+Y$5) -> 5229.9115 | Y15: =$N15*(1+Z$5) -> 5229.9115 | Z15: =$N15*(1+AA$5) -> 5229.9115 | ... AD15: =$N15*(1+AE$5) -> 5229.9115 | AE15: =SUM(S15:AD15) -> 62758.938 | AH15: P8 | AI15: =$N15*(1+AI$5) -> 5229.9115 | AJ15: =$N15*(1+AJ$5) -> 5229.9115 | AK15: =$N15*(1+AK$5) -> 5229.9115 | AL15: =$N15*(1+AL$5) -> 5229.9115 | AM15: =$N15*(1+AM$5) -> 5229.9115 | AN15: =$N15*(1+AN$5) -> 5229.9115 | AO15: =$N15*(1+AO$5) -> 5229.9115 | AP15: =$N15*(1+AP$5) -> 5229.9115 | ... AT15: =$N15*(1+AT$5) -> 5229.9115 | AU15: =SUM(AI15:AT15) -> 62758.938
A16: (Trim 1 et 4 seulement) | B16: P9 | C16: =Données!N14 -> 1270.4309 | D16: =C16*(1+D$5) -> 1397.474 | E16: =D16*(1+E$5) -> 1607.0951 | L16: =E16*(1+F$5) -> 1848.1594 | M16: =L16*(1+G$5) -> 2125.3833 | N16: =M16*(1+H$5) -> 2337.9216 | O16: =SUM(C16:N16) -> 10586.464 | R16: P9 | S16: =1270.4309063893*1+(I5) -> 1270.5309 | T16: =1397.47399702823*1+(J5) -> 1397.524 | U16: =1607.09509658247*1+(L5) -> 1607.1451 | AB16: =2977.08013091881*1+(T$5) -> 2977.0801 | AC16: =2977.08013091881*1+(U$5) -> 2977.0801 | AD16: =2977.08013091881*1+(V$5) -> 2977.0801 | AE16: =SUM(S16:AD16) -> 13206.44 | AH16: P9 | AI16: =1270.4309063893*1+(W$3) -> 1270.4309 | AJ16: =1270.4309063893*1+(X$3) -> 1270.4309 | AK16: =1270.4309063893*1+(Y$3) -> 1270.4309 | AR16: =2977.08013091881*1+(AC$5) -> 2977.0801 | AS16: =2977.08013091881*1+(AD$5) -> 2977.0801 | AT16: =2977.08013091881*1+(AE$5) -> 2977.0801 | AU16: =SUM(AI16:AT16) -> 12742.533
B17: P10 | C17: =Données!N15 -> 334.32392 | D17: =C17*(1+D$5) -> 367.75632 | E17: =D17*(1+E$5) -> 422.91976 | F17: =E17*(1+F$5) -> 486.35773 | G17: =F17*(1+G$5) -> 559.31139 | H17: =G17*(1+H$5) -> 615.24252 | I17: =H17*(1+I$5) -> 676.76678 | J17: =I17*(1+J$5) -> 710.60512 | K17: =J17*(1+K$5) -> 746.13537 | ... N17: =M17*(1+N$5) -> 783.44214 | O17: =SUM(C17:N17) -> 7269.7453 | R17: P10 | S17: =$N17*(1+T$5) -> 783.44214 | T17: =$N17*(1+U$5) -> 783.44214 | U17: =$N17*(1+V$5) -> 783.44214 | V17: =$N17*(1+W$5) -> 783.44214 | W17: =$N17*(1+X$5) -> 783.44214 | X17: =$N17*(1+Y$5) -> 783.44214 | Y17: =$N17*(1+Z$5) -> 783.44214 | Z17: =$N17*(1+AA$5) -> 783.44214 | ... AD17: =$N17*(1+AE$5) -> 783.44214 | AE17: =SUM(S17:AD17) -> 9401.3057 | AH17: P10 | AI17: =$N17*(1+AI$5) -> 783.44214 | AJ17: =$N17*(1+AJ$5) -> 783.44214 | AK17: =$N17*(1+AK$5) -> 783.44214 | AL17: =$N17*(1+AL$5) -> 783.44214 | AM17: =$N17*(1+AM$5) -> 783.44214 | AN17: =$N17*(1+AN$5) -> 783.44214 | AO17: =$N17*(1+AO$5) -> 783.44214 | AP17: =$N17*(1+AP$5) -> 783.44214 | ... AT17: =$N17*(1+AT$5) -> 783.44214 | AU17: =SUM(AI17:AT17) -> 9401.3057
A18: (Trim 2 et 4 seulement) | B18: P11 | F18: =Données!N16*(1+Données!F$26) -> 335.37707 | G18: =F18*(1+$D$5) -> 368.91477 | H18: =G18*(1+$E$5) -> 424.25199 | L18: =H18*(1+F$5) -> 487.88979 | M18: =L18*(1+$G$5) -> 561.07326 | N18: =M18*(1+$H$5) -> 617.18058 | O18: =SUM(C18:N18) -> 2794.6875 | R18: P11 | V18: =335.377067928969*1+($M5) -> 335.37707 | W18: =368.914774721866*1+(N$5) -> 368.91477 | X18: =424.251990930146*1+(S5) -> 424.25199 | AB18: =487.889789569668*1+(T$5) -> 487.88979 | AC18: =487.889789569668*1+(U$5) -> 487.88979 | AD18: =487.889789569668*1+(V$5) -> 487.88979 | AE18: =SUM(S18:AD18) -> 2592.2132 | AH18: P11 | AL18: =335.377067928969*1+(Z$5) -> 335.37707 | AM18: =335.377067928969*1+(AA$5) -> 335.37707 | AN18: =335.377067928969*1+(AB$5) -> 335.37707 | AR18: =487.889789569668*1+(AC$5) -> 487.88979 | AS18: =487.889789569668*1+(AD$5) -> 487.88979 | AT18: =487.889789569668*1+(AE$5) -> 487.88979 | AU18: =SUM(AI18:AT18) -> 2469.8006
A19: (Trim 2 et 4 seulement) | B19: P12 | F19: =Données!N17*(1+Données!F$26) -> 1000.3488 | G19: =F19*(1+$D$5) -> 1100.3837 | H19: =G19*(1+$E$5) -> 1265.4413 | L19: =H19*(1+F$5) -> 1455.2575 | M19: =L19*(1+$G$5) -> 1673.5461 | N19: =M19*(1+$H$5) -> 1840.9007 | O19: =SUM(C19:N19) -> 8335.8781 | R19: P12 | V19: =1000.34884054675*1+(M5) -> 1000.3488 | W19: =1100.38372460143*1+(N5) -> 1100.3837 | X19: =1265.44128329164*1+(S5) -> 1265.4413 | AB19: =1455.25747578539*1+(T$5) -> 1455.2575 | AC19: =1455.25747578539*1+(U$5) -> 1455.2575 | AD19: =1455.25747578539*1+(V$5) -> 1455.2575 | AE19: =SUM(S19:AD19) -> 7731.9463 | AH19: P12 | AL19: =1000.34884054675*1+(Z$5) -> 1000.3488 | AM19: =1000.34884054675*1+(AA$5) -> 1000.3488 | AN19: =1000.34884054675*1+(AB$5) -> 1000.3488 | AR19: =1455.25747578539*1+(AC$5) -> 1455.2575 | AS19: =1455.25747578539*1+(AD$5) -> 1455.2575 | AT19: =1455.25747578539*1+(AE$5) -> 1455.2575 | AU19: =SUM(AI19:AT19) -> 7366.8189
A20: (Trim 2 et 4 seulement) | B20: P13 | F20: =Données!N18*(1+Données!F$26) -> 404.76543 | G20: =F20*(1+$D$5) -> 445.24197 | H20: =G20*(1+$E$5) -> 512.02826 | L20: =H20*(1+F$5) -> 588.8325 | M20: =L20*(1+$G$5) -> 677.15738 | N20: =M20*(1+$H$5) -> 744.87312 | O20: =SUM(C20:N20) -> 3372.8987 | R20: P13 | V20: =404.765426810825*1+(M5) -> 404.76543 | W20: =445.241969491907*1+(N5) -> 445.24197 | X20: =512.028264915693*1+(S5) -> 512.02826 | AB20: =588.832504653047*1+(T$5) -> 588.8325 | AC20: =588.832504653047*1+(U$5) -> 588.8325 | AD20: =588.832504653047*1+(V$5) -> 588.8325 | AE20: =SUM(S20:AD20) -> 3128.5332 | AH20: P13 | AL20: =404.765426810825*1+(Z$5) -> 404.76543 | AM20: =404.765426810825*1+(AA$5) -> 404.76543 | AN20: =404.765426810825*1+(AB$5) -> 404.76543 | AR20: =588.832504653047*1+(AC$5) -> 588.8325 | AS20: =588.832504653047*1+(AD$5) -> 588.8325 | AT20: =588.832504653047*1+(AE$5) -> 588.8325 | AU20: =SUM(AI20:AT20) -> 2980.7938
B21: Total | C21: =SUM(C8:C20) -> 11771.174 | D21: =SUM(D8:D20) -> 12948.291 | E21: =SUM(E8:E20) -> 14890.535 | F21: =SUM(F8:F20) -> 14740.293 | G21: =SUM(G8:G20) -> 16864.312 | H21: =SUM(H8:H20) -> 18646.471 | I21: =SUM(I8:I20) -> 18089.224 | J21: =SUM(J8:J20) -> 18993.685 | ... O21: =SUM(O8:O20) -> 232440.21 | S21: =SUM(S8:S20) -> 23775.905 | T21: =SUM(T8:T20) -> 24059.261 | U21: =SUM(U8:U20) -> 24527.047 | V21: =SUM(V8:V20) -> 22681.029 | W21: =SUM(W8:W20) -> 22855.078 | X21: =SUM(X8:X20) -> 23142.259 | Y21: =SUM(Y8:Y20) -> 20940.538 | Z21: =SUM(Z8:Z20) -> 20940.538 | ... AE21: =SUM(AE8:AE20) -> 294210.52 | AI21: =SUM(AI8:AI20) -> 23775.605 | AJ21: =SUM(AJ8:AJ20) -> 23775.605 | AK21: =SUM(AK8:AK20) -> 23775.605 | AL21: =SUM(AL8:AL20) -> 22681.029 | AM21: =SUM(AM8:AM20) -> 22681.029 | AN21: =SUM(AN8:AN20) -> 22681.029 | AO21: =SUM(AO8:AO20) -> 20940.538 | AP21: =SUM(AP8:AP20) -> 20940.538 | ... AU21: =SUM(AU8:AU20) -> 292539.84
A23: Prix de vente unitaire | B23: Produits | C23: Mois 1 | D23: Mois 2 | E23: Mois 3 | F23: Mois 4 | G23: Mois 5 | H23: Mois 6 | I23: Mois 7 | J23: Mois 8 | K23: Mois 9 | L23: Mois 10 | M23: Mois 11 | N23: Mois 12 | O23: Année 1 | Q23: Prix de vente unitaire | R23: Produits | S23: Mois 1 | T23: Mois 2 | U23: Mois 3 | V23: Mois 4 | W23: Mois 5 | X23: Mois 6 | Y23: Mois 7 | Z23: Mois 8 | AA23: Mois 9 | AB23: Mois 10 | AC23: Mois 11 | AD23: Mois 12 | AE23: Année 2 | AG23: Prix de vente unitaire | AH23: Produits | AI23: Mois 1 | AJ23: Mois 2 | AK23: Mois 3 | AL23: Mois 4 | AM23: Mois 5 | AN23: Mois 6 | AO23: Mois 7 | AP23: Mois 8 | AQ23: Mois 9 | AR23: Mois 10 | AS23: Mois 11 | AT23: Mois 12 | AU23: Année 3
A24: {=Données!$I$6:$I$18} -> 10.87 | B24: P1 | C24: =C8*$A24 -> 16910.684 | D24: =D8*$A24 -> 18601.752 | E24: =E8*$A24 -> 21392.015 | F24: =F8*$A24 -> 24600.817 | G24: =G8*$A24 -> 28290.939 | H24: =H8*$A24 -> 31120.033 | I24: =I8*$A24 -> 34232.037 | J24: =J8*$A24 -> 35943.638 | ... N24: =N8*$A24 -> 39627.861 | O24: =SUM(C24:N24) -> 367716.32 | Q24: =A24 -> 10.87 | R24: P1 | S24: =$Q24*S8 -> 39627.861 | T24: =$Q24*T8 -> 39627.861 | U24: =$Q24*U8 -> 39627.861 | V24: =$Q24*V8 -> 39627.861 | W24: =$Q24*W8 -> 39627.861 | X24: =$Q24*X8 -> 39627.861 | Y24: =$Q24*Y8 -> 39627.861 | Z24: =$Q24*Z8 -> 39627.861 | ... AD24: =$Q24*AD8 -> 39627.861 | AE24: =SUM(S24:AD24) -> 475534.34 | AG24: =Q24 -> 10.87 | AH24: P1 | AI24: =AI8*$AG24 -> 39627.861 | AJ24: =AJ8*$AG24 -> 39627.861 | AK24: =AK8*$AG24 -> 39627.861 | AL24: =AL8*$AG24 -> 39627.861 | AM24: =AM8*$AG24 -> 39627.861 | AN24: =AN8*$AG24 -> 39627.861 | AO24: =AO8*$AG24 -> 39627.861 | AP24: =AP8*$AG24 -> 39627.861 | ... AT24: =AT8*$AG24 -> 39627.861 | AU24: =SUM(AI24:AT24) -> 475534.34
A25: 21.74 | B25: P2 | C25: =C9*$A25 -> 39635.929 | D25: =D9*$A25 -> 43599.522 | E25: =E9*$A25 -> 50139.45 | F25: =F9*$A25 -> 57660.367 | G25: =G9*$A25 -> 66309.422 | H25: =H9*$A25 -> 72940.365 | I25: =I9*$A25 -> 80234.401 | J25: =J9*$A25 -> 84246.121 | ... N25: =N9*$A25 -> 92881.348 | O25: =SUM(C25:N25) -> 861868.05 | Q25: =A25 -> 21.74 | R25: P2 | S25: =$Q25*S9 -> 92881.348 | T25: =$Q25*T9 -> 92881.348 | U25: =$Q25*U9 -> 92881.348 | V25: =$Q25*V9 -> 92881.348 | W25: =$Q25*W9 -> 92881.348 | X25: =$Q25*X9 -> 92881.348 | Y25: =$Q25*Y9 -> 92881.348 | Z25: =$Q25*Z9 -> 92881.348 | ... AD25: =$Q25*AD9 -> 92881.348 | AE25: =SUM(S25:AD25) -> 1114576.2 | AG25: =Q25 -> 21.74 | AH25: P2 | AI25: =AI9*$AG25 -> 92881.348 | AJ25: =AJ9*$AG25 -> 92881.348 | AK25: =AK9*$AG25 -> 92881.348 | AL25: =AL9*$AG25 -> 92881.348 | AM25: =AM9*$AG25 -> 92881.348 | AN25: =AN9*$AG25 -> 92881.348 | AO25: =AO9*$AG25 -> 92881.348 | AP25: =AP9*$AG25 -> 92881.348 | ... AT25: =AT9*$AG25 -> 92881.348 | AU25: =SUM(AI25:AT25) -> 1114576.2
A26: 35.02 | B26: P3 | C26: =C10*$A26 -> 37725.854 | D26: =D10*$A26 -> 41498.44 | E26: =E10*$A26 -> 47723.206 | F26: =F10*$A26 -> 0 | G26: =G10*$A26 -> 0 | H26: =H10*$A26 -> 0 | I26: =I10*$A26 -> 0 | J26: =J10*$A26 -> 0 | ... N26: =N10*$A26 -> 69425.334 | O26: =SUM(C26:N26) -> 314368.46 | Q26: =A26 -> 35.02 | R26: P3 | S26: =$Q26*S10 -> 37729.356 | T26: =$Q26*T10 -> 41500.191 | U26: =$Q26*U10 -> 47724.957 | V26: =$Q26*V10 -> 0 | W26: =$Q26*W10 -> 0 | X26: =$Q26*X10 -> 0 | Y26: =$Q26*Y10 -> 0 | Z26: =$Q26*Z10 -> 0 | ... AD26: =$Q26*AD10 -> 88405.352 | AE26: =SUM(S26:AD26) -> 392170.56 | AG26: =Q26 -> 35.02 | AH26: P3 | AI26: =AI10*$AG26 -> 37725.854 | AJ26: =AJ10*$AG26 -> 37725.854 | AK26: =AK10*$AG26 -> 37725.854 | AL26: =AL10*$AG26 -> 0 | AM26: =AM10*$AG26 -> 0 | AN26: =AN10*$AG26 -> 0 | AO26: =AO10*$AG26 -> 0 | AP26: =AP10*$AG26 -> 0 | ... AT26: =AT10*$AG26 -> 88405.352 | AU26: =SUM(AI26:AT26) -> 378393.62
A27: 42.26 | B27: P4 | C27: =C11*$A27 -> 35917.86 | D27: =D11*$A27 -> 39509.646 | E27: =E11*$A27 -> 45436.093 | F27: =F11*$A27 -> 52251.507 | G27: =G11*$A27 -> 60089.233 | H27: =H11*$A27 -> 66098.157 | I27: =I11*$A27 -> 72707.972 | J27: =J11*$A27 -> 76343.371 | ... N27: =N11*$A27 -> 84168.567 | O27: =SUM(C27:N27) -> 781020.08 | Q27: =A27 -> 42.26 | R27: P4 | S27: =$Q27*S11 -> 84168.567 | T27: =$Q27*T11 -> 84168.567 | U27: =$Q27*U11 -> 84168.567 | V27: =$Q27*V11 -> 84168.567 | W27: =$Q27*W11 -> 84168.567 | X27: =$Q27*X11 -> 84168.567 | Y27: =$Q27*Y11 -> 84168.567 | Z27: =$Q27*Z11 -> 84168.567 | ... AD27: =$Q27*AD11 -> 84168.567 | AE27: =SUM(S27:AD27) -> 1010022.8 | AG27: =Q27 -> 42.26 | AH27: P4 | AI27: =AI11*$AG27 -> 84168.567 | AJ27: =AJ11*$AG27 -> 84168.567 | AK27: =AK11*$AG27 -> 84168.567 | AL27: =AL11*$AG27 -> 84168.567 | AM27: =AM11*$AG27 -> 84168.567 | AN27: =AN11*$AG27 -> 84168.567 | AO27: =AO11*$AG27 -> 84168.567 | AP27: =AP11*$AG27 -> 84168.567 | ... AT27: =AT11*$AG27 -> 84168.567 | AU27: =SUM(AI27:AT27) -> 1010022.8
A28: 59.17 | B28: P5 | C28: =C12*$A28 -> 83523.774 | D28: =D12*$A28 -> 91876.152 | E28: =E12*$A28 -> 105657.57 | F28: =F12*$A28 -> 121506.21 | G28: =G12*$A28 -> 139732.14 | H28: =H12*$A28 -> 153705.36 | I28: =I12*$A28 -> 169075.89 | J28: =J12*$A28 -> 177529.69 | ... N28: =N12*$A28 -> 195726.48 | O28: =SUM(C28:N28) -> 1816192.4 | Q28: =A28 -> 59.17 | R28: P5 | S28: =$Q28*S12 -> 195726.48 | T28: =$Q28*T12 -> 195726.48 | U28: =$Q28*U12 -> 195726.48 | V28: =$Q28*V12 -> 195726.48 | W28: =$Q28*W12 -> 195726.48 | X28: =$Q28*X12 -> 195726.48 | Y28: =$Q28*Y12 -> 195726.48 | Z28: =$Q28*Z12 -> 195726.48 | ... AD28: =$Q28*AD12 -> 195726.48 | AE28: =SUM(S28:AD28) -> 2348717.8 | AG28: =Q28 -> 59.17 | AH28: P5 | AI28: =AI12*$AG28 -> 195726.48 | AJ28: =AJ12*$AG28 -> 195726.48 | AK28: =AK12*$AG28 -> 195726.48 | AL28: =AL12*$AG28 -> 195726.48 | AM28: =AM12*$AG28 -> 195726.48 | AN28: =AN12*$AG28 -> 195726.48 | AO28: =AO12*$AG28 -> 195726.48 | AP28: =AP12*$AG28 -> 195726.48 | ... AT28: =AT12*$AG28 -> 195726.48 | AU28: =SUM(AI28:AT28) -> 2348717.8
A29: 64 | B29: P6 | C29: =C13*$A29 -> 31191.679 | D29: =D13*$A29 -> 34310.847 | E29: =E13*$A29 -> 39457.474 | F29: =F13*$A29 -> 0 | G29: =G13*$A29 -> 0 | H29: =H13*$A29 -> 0 | I29: =I13*$A29 -> 0 | J29: =J13*$A29 -> 0 | ... N29: =N13*$A29 -> 57400.76 | O29: =SUM(C29:N29) -> 259919.36 | Q29: =A29 -> 64 | R29: P6 | S29: =$Q29*S13 -> 31198.079 | T29: =$Q29*T13 -> 34314.047 | U29: =$Q29*U13 -> 39460.674 | V29: =$Q29*V13 -> 0 | W29: =$Q29*W13 -> 0 | X29: =$Q29*X13 -> 0 | Y29: =$Q29*Y13 -> 0 | Z29: =$Q29*Z13 -> 0 | ... AD29: =$Q29*AD13 -> 73093.411 | AE29: =SUM(S29:AD29) -> 324253.03 | AG29: =Q29 -> 64 | AH29: P6 | AI29: =AI13*$AG29 -> 31191.679 | AJ29: =AJ13*$AG29 -> 31191.679 | AK29: =AK13*$AG29 -> 31191.679 | AL29: =AL13*$AG29 -> 0 | AM29: =AM13*$AG29 -> 0 | AN29: =AN13*$AG29 -> 0 | AO29: =AO13*$AG29 -> 0 | AP29: =AP13*$AG29 -> 0 | ... AT29: =AT13*$AG29 -> 73093.411 | AU29: =SUM(AI29:AT29) -> 312855.27
A30: 82.11 | B30: P7 | C30: =C14*$A30 -> 59904.918 | D30: =D14*$A30 -> 65895.41 | E30: =E14*$A30 -> 75779.722 | F30: =F14*$A30 -> 87146.68 | G30: =G14*$A30 -> 100218.68 | H30: =H14*$A30 -> 110240.55 | I30: =I14*$A30 -> 121264.61 | J30: =J14*$A30 -> 127327.84 | ... N30: =N14*$A30 -> 140378.94 | O30: =SUM(C30:N30) -> 1302609.4 | Q30: =A30 -> 82.11 | R30: P7 | S30: =$Q30*S14 -> 140378.94 | T30: =$Q30*T14 -> 140378.94 | U30: =$Q30*U14 -> 140378.94 | V30: =$Q30*V14 -> 140378.94 | W30: =$Q30*W14 -> 140378.94 | X30: =$Q30*X14 -> 140378.94 | Y30: =$Q30*Y14 -> 140378.94 | Z30: =$Q30*Z14 -> 140378.94 | ... AD30: =$Q30*AD14 -> 140378.94 | AE30: =SUM(S30:AD30) -> 1684547.3 | AG30: =Q30 -> 82.11 | AH30: P7 | AI30: =AI14*$AG30 -> 140378.94 | AJ30: =AJ14*$AG30 -> 140378.94 | AK30: =AK14*$AG30 -> 140378.94 | AL30: =AL14*$AG30 -> 140378.94 | AM30: =AM14*$AG30 -> 140378.94 | AN30: =AN14*$AG30 -> 140378.94 | AO30: =AO14*$AG30 -> 140378.94 | AP30: =AP14*$AG30 -> 140378.94 | ... AT30: =AT14*$AG30 -> 140378.94 | AU30: =SUM(AI30:AT30) -> 1684547.3
A31: 85.73 | B31: P8 | C31: =C15*$A31 -> 191332.04 | D31: =D15*$A31 -> 210465.24 | E31: =E15*$A31 -> 242035.03 | F31: =F15*$A31 -> 278340.28 | G31: =G15*$A31 -> 320091.32 | H31: =H15*$A31 -> 352100.45 | I31: =I15*$A31 -> 387310.5 | J31: =J15*$A31 -> 406676.02 | ... N31: =N15*$A31 -> 448360.32 | O31: =SUM(C31:N31) -> 4160441.6 | Q31: =A31 -> 85.73 | R31: P8 | S31: =$Q31*S15 -> 448360.32 | T31: =$Q31*T15 -> 448360.32 | U31: =$Q31*U15 -> 448360.32 | V31: =$Q31*V15 -> 448360.32 | W31: =$Q31*W15 -> 448360.32 | X31: =$Q31*X15 -> 448360.32 | Y31: =$Q31*Y15 -> 448360.32 | Z31: =$Q31*Z15 -> 448360.32 | ... AD31: =$Q31*AD15 -> 448360.32 | AE31: =SUM(S31:AD31) -> 5380323.8 | AG31: =Q31 -> 85.73 | AH31: P8 | AI31: =AI15*$AG31 -> 448360.32 | AJ31: =AJ15*$AG31 -> 448360.32 | AK31: =AK15*$AG31 -> 448360.32 | AL31: =AL15*$AG31 -> 448360.32 | AM31: =AM15*$AG31 -> 448360.32 | AN31: =AN15*$AG31 -> 448360.32 | AO31: =AO15*$AG31 -> 448360.32 | AP31: =AP15*$AG31 -> 448360.32 | ... AT31: =AT15*$AG31 -> 448360.32 | AU31: =SUM(AI31:AT31) -> 5380323.8
A32: 108.68 | B32: P9 | C32: =C16*$A32 -> 138070.43 | D32: =D16*$A32 -> 151877.47 | E32: =E16*$A32 -> 174659.1 | F32: =F16*$A32 -> 0 | G32: =G16*$A32 -> 0 | H32: =H16*$A32 -> 0 | I32: =I16*$A32 -> 0 | J32: =J16*$A32 -> 0 | ... N32: =N16*$A32 -> 254085.32 | O32: =SUM(C32:N32) -> 1150536.9 | Q32: =A32 -> 108.68 | R32: P9 | S32: =$Q32*S16 -> 138081.3 | T32: =$Q32*T16 -> 151882.91 | U32: =$Q32*U16 -> 174664.53 | V32: =$Q32*V16 -> 0 | W32: =$Q32*W16 -> 0 | X32: =$Q32*X16 -> 0 | Y32: =$Q32*Y16 -> 0 | Z32: =$Q32*Z16 -> 0 | ... AD32: =$Q32*AD16 -> 323549.07 | AE32: =SUM(S32:AD32) -> 1435275.9 | AG32: =Q32 -> 108.68 | AH32: P9 | AI32: =AI16*$AG32 -> 138070.43 | AJ32: =AJ16*$AG32 -> 138070.43 | AK32: =AK16*$AG32 -> 138070.43 | AL32: =AL16*$AG32 -> 0 | AM32: =AM16*$AG32 -> 0 | AN32: =AN16*$AG32 -> 0 | AO32: =AO16*$AG32 -> 0 | AP32: =AP16*$AG32 -> 0 | ... AT32: =AT16*$AG32 -> 323549.07 | AU32: =SUM(AI32:AT32) -> 1384858.5
A33: 107.47 | B33: P10 | C33: =C17*$A33 -> 35929.792 | D33: =D17*$A33 -> 39522.771 | E33: =E17*$A33 -> 45451.187 | F33: =F17*$A33 -> 52268.865 | G33: =G17*$A33 -> 60109.195 | H33: =H17*$A33 -> 66120.114 | I33: =I17*$A33 -> 72732.125 | J33: =J17*$A33 -> 76368.732 | ... N33: =N17*$A33 -> 84196.527 | O33: =SUM(C33:N33) -> 781279.53 | Q33: =A33 -> 107.47 | R33: P10 | S33: =$Q33*S17 -> 84196.527 | T33: =$Q33*T17 -> 84196.527 | U33: =$Q33*U17 -> 84196.527 | V33: =$Q33*V17 -> 84196.527 | W33: =$Q33*W17 -> 84196.527 | X33: =$Q33*X17 -> 84196.527 | Y33: =$Q33*Y17 -> 84196.527 | Z33: =$Q33*Z17 -> 84196.527 | ... AD33: =$Q33*AD17 -> 84196.527 | AE33: =SUM(S33:AD33) -> 1010358.3 | AG33: =Q33 -> 107.47 | AH33: P10 | AI33: =AI17*$AG33 -> 84196.527 | AJ33: =AJ17*$AG33 -> 84196.527 | AK33: =AK17*$AG33 -> 84196.527 | AL33: =AL17*$AG33 -> 84196.527 | AM33: =AM17*$AG33 -> 84196.527 | AN33: =AN17*$AG33 -> 84196.527 | AO33: =AO17*$AG33 -> 84196.527 | AP33: =AP17*$AG33 -> 84196.527 | ... AT33: =AT17*$AG33 -> 84196.527 | AU33: =SUM(AI33:AT33) -> 1010358.3
A34: 36.23 | B34: P11 | C34: =C18*$A34 -> 0 | D34: =D18*$A34 -> 0 | E34: =E18*$A34 -> 0 | F34: =F18*$A34 -> 12150.711 | G34: =G18*$A34 -> 13365.782 | H34: =H18*$A34 -> 15370.65 | I34: =I18*$A34 -> 0 | J34: =J18*$A34 -> 0 | ... N34: =N18*$A34 -> 22360.453 | O34: =SUM(C34:N34) -> 101251.53 | Q34: =A34 -> 36.23 | R34: P11 | S34: =$Q34*S18 -> 0 | T34: =$Q34*T18 -> 0 | U34: =$Q34*U18 -> 0 | V34: =$Q34*V18 -> 12150.711 | W34: =$Q34*W18 -> 13365.782 | X34: =$Q34*X18 -> 15370.65 | Y34: =$Q34*Y18 -> 0 | Z34: =$Q34*Z18 -> 0 | ... AD34: =$Q34*AD18 -> 17676.247 | AE34: =SUM(S34:AD34) -> 93915.884 | AG34: =Q34 -> 36.23 | AH34: P11 | AI34: =AI18*$AG34 -> 0 | AJ34: =AJ18*$AG34 -> 0 | AK34: =AK18*$AG34 -> 0 | AL34: =AL18*$AG34 -> 12150.711 | AM34: =AM18*$AG34 -> 12150.711 | AN34: =AN18*$AG34 -> 12150.711 | AO34: =AO18*$AG34 -> 0 | AP34: =AP18*$AG34 -> 0 | ... AT34: =AT18*$AG34 -> 17676.247 | AU34: =SUM(AI34:AT34) -> 89480.875
A35: 63.4 | B35: P12 | C35: =C19*$A35 -> 0 | D35: =D19*$A35 -> 0 | E35: =E19*$A35 -> 0 | F35: =F19*$A35 -> 63422.116 | G35: =G19*$A35 -> 69764.328 | H35: =H19*$A35 -> 80228.977 | I35: =I19*$A35 -> 0 | J35: =J19*$A35 -> 0 | ... N35: =N19*$A35 -> 116713.1 | O35: =SUM(C35:N35) -> 528494.67 | Q35: =A35 -> 63.4 | R35: P12 | S35: =$Q35*S19 -> 0 | T35: =$Q35*T19 -> 0 | U35: =$Q35*U19 -> 0 | V35: =$Q35*V19 -> 63422.116 | W35: =$Q35*W19 -> 69764.328 | X35: =$Q35*X19 -> 80228.977 | Y35: =$Q35*Y19 -> 0 | Z35: =$Q35*Z19 -> 0 | ... AD35: =$Q35*AD19 -> 92263.324 | AE35: =SUM(S35:AD35) -> 490205.39 | AG35: =Q35 -> 63.4 | AH35: P12 | AI35: =AI19*$AG35 -> 0 | AJ35: =AJ19*$AG35 -> 0 | AK35: =AK19*$AG35 -> 0 | AL35: =AL19*$AG35 -> 63422.116 | AM35: =AM19*$AG35 -> 63422.116 | AN35: =AN19*$AG35 -> 63422.116 | AO35: =AO19*$AG35 -> 0 | AP35: =AP19*$AG35 -> 0 | ... AT35: =AT19*$AG35 -> 92263.324 | AU35: =SUM(AI35:AT35) -> 467056.32
A36: 99.62 | B36: P13 | C36: =C20*$A36 -> 0 | D36: =D20*$A36 -> 0 | E36: =E20*$A36 -> 0 | F36: =F20*$A36 -> 40322.732 | G36: =G20*$A36 -> 44355.005 | H36: =H20*$A36 -> 51008.256 | I36: =I20*$A36 -> 0 | J36: =J20*$A36 -> 0 | ... N36: =N20*$A36 -> 74204.26 | O36: =SUM(C36:N36) -> 336008.16 | Q36: =A36 -> 99.62 | R36: P13 | S36: =$Q36*S20 -> 0 | T36: =$Q36*T20 -> 0 | U36: =$Q36*U20 -> 0 | V36: =$Q36*V20 -> 40322.732 | W36: =$Q36*W20 -> 44355.005 | X36: =$Q36*X20 -> 51008.256 | Y36: =$Q36*Y20 -> 0 | Z36: =$Q36*Z20 -> 0 | ... AD36: =$Q36*AD20 -> 58659.494 | AE36: =SUM(S36:AD36) -> 311664.47 | AG36: =Q36 -> 99.62 | AH36: P13 | AI36: =AI20*$AG36 -> 0 | AJ36: =AJ20*$AG36 -> 0 | AK36: =AK20*$AG36 -> 0 | AL36: =AL20*$AG36 -> 40322.732 | AM36: =AM20*$AG36 -> 40322.732 | AN36: =AN20*$AG36 -> 40322.732 | AO36: =AO20*$AG36 -> 0 | AP36: =AP20*$AG36 -> 0 | ... AT36: =AT20*$AG36 -> 58659.494 | AU36: =SUM(AI36:AT36) -> 296946.68
C37: =SUM(C24:C36) -> 670142.96 | D37: =SUM(D24:D36) -> 737157.25 | E37: =SUM(E24:E36) -> 847730.84 | F37: =SUM(F24:F36) -> 789670.28 | G37: =SUM(G24:G36) -> 902326.05 | H37: =SUM(H24:H36) -> 998932.91 | I37: =SUM(I24:I36) -> 937557.53 | J37: =SUM(J24:J36) -> 984435.41 | ... O37: =SUM(O24:O36) -> 12761707 | S37: =SUM(S24:S36) -> 1292348.8 | T37: =SUM(T24:T36) -> 1313037.2 | U37: =SUM(U24:U36) -> 1347190.2 | V37: =SUM(V24:V36) -> 1201235.6 | W37: =SUM(W24:W36) -> 1212825.2 | X37: =SUM(X24:X36) -> 1231947.9 | Y37: =SUM(Y24:Y36) -> 1085340 | Z37: =SUM(Z24:Z36) -> 1085340 | ... AE37: =SUM(AE24:AE36) -> 16071566 | AI37: =SUM(AI24:AI36) -> 1292328 | AJ37: =SUM(AJ24:AJ36) -> 1292328 | AK37: =SUM(AK24:AK36) -> 1292328 | AL37: =SUM(AL24:AL36) -> 1201235.6 | AM37: =SUM(AM24:AM36) -> 1201235.6 | AN37: =SUM(AN24:AN36) -> 1201235.6 | AO37: =SUM(AO24:AO36) -> 1085340 | AP37: =SUM(AP24:AP36) -> 1085340 | ... AU37: =SUM(AU24:AU36) -> 15953672
B40: Année 1 | C40: Année 2 | D40: Année 3
A41: Trimestre 1 | B41: =SUM(C21+D21+E21) -> 39610 | C41: =SUM(S21:U21) -> 72362.214 | D41: =SUM(AI21:AK21) -> 71326.814
A42: Trimestre 2 | B42: =SUM(E21+F21+G21) -> 46495.14 | C42: =SUM(V21:X21) -> 68678.367 | D42: =SUM(AL21:AN21) -> 68043.088
A43: Trimestre 3 | B43: =SUM(I21+J21+K21) -> 57026.279 | C43: =SUM(Y21:AA21) -> 62821.614 | D43: =SUM(AO21:AQ21) -> 62821.614
A44: Trimestre 4 | B44: =SUM(L21:N21) -> 85552.855 | C44: =SUM(AB21:AD21) -> 90348.321 | D44: =SUM(AR21:AT21) -> 90348.321

Sheet S2  - Inventaire départ
A1: Évaluation de l'inventaire au démarrage TRIM 1: | H1: Données d'entreprise à ajuster en fonction de la situation
E2: (Plafond ou Plancher) | K2: Tableau de comparaison des transporteurs:
C3: Ventes TRIM 1 | D3: Lot | E3: Qté à commander | F3: Coût unitaire | G3: Coût total | H3: Volume unitaire (M3) | I3: Volume total (M3) | M3: M3 | N3: Coût | O3: Nombre de voyages | P3: Coût total
B4: P1 | C4: ='S1 - projections'!C8+'S1 - projections'!D8+'S1 - projections'!E8 -> 5235 | D4: =Données!J6 -> 50 | E4: =CEILING(C4,D4) -> 5250 | F4: =Données!H6 -> 6.75 | G4: =E4*F4 -> 35437.5 | H4: =Données!G6 -> 0.18 | I4: =E4*H4 -> 945 | K4: FTL | L4: Fournisseur: | M4: 150 | N4: 925 | O4: =I23 -> 32 | P4: =O4*N4 -> 29600 | Q4: =P4+P5 -> 30250
B5: P2 | C5: ='S1 - projections'!C9+'S1 - projections'!D9+'S1 - projections'!E9 -> 6135 | D5: =Données!J7 -> 100 | E5: =CEILING(C5,D5) -> 6200 | F5: =Données!H7 -> 13.5 | G5: =E5*F5 -> 83700 | H5: =Données!G7 -> 0.225 | I5: =E5*H5 -> 1395 | M5: 100 | N5: 650 | O5: =ROUNDUP(I26,0) -> 1 | P5: =O5*N5 -> 650
B6: P3 | C6: ='S1 - projections'!C10+'S1 - projections'!D10+'S1 - projections'!E10 -> 3625 | D6: =Données!J8 -> 100 | E6: =CEILING(C6,D6) -> 3700 | F6: =Données!H8 -> 20 | G6: =E6*F6 -> 74000 | H6: =Données!G8 -> 0.675 | I6: =E6*H6 -> 2497.5 | K6: LTL | L6: Desgagné: | M6: 150 | N6: 865 | O6: =I23 -> 32 | P6: =O6*N6 -> 27680 | Q6: =P6+P7 -> 27959.375
B7: P4 | C7: ='S1 - projections'!C11+'S1 - projections'!D11+'S1 - projections'!E11 -> 2860 | D7: =Données!J9 -> 100 | E7: =CEILING(C7,D7) -> 2900 | F7: =Données!H9 -> 29 | G7: =E7*F7 -> 84100 | H7: =Données!G9 -> 0.5 | I7: =E7*H7 -> 1450 | M7: 100 | N7: 745 | O7: =I26 -> 0.375 | P7: =O7*N7 -> 279.375
B8: P5 | C8: ='S1 - projections'!C12+'S1 - projections'!D12+'S1 - projections'!E12 -> 4750 | D8: =Données!J10 -> 50 | E8: =CEILING(C8,D8) -> 4750 | F8: =Données!H10 -> 35 | G8: =E8*F8 -> 166250 | H8: =Données!G10 -> 0.75 | I8: =E8*H8 -> 3562.5
B9: P6 | C9: ='S1 - projections'!C13+'S1 - projections'!D13+'S1 - projections'!E13 -> 1640 | D9: =Données!J11 -> 100 | E9: =CEILING(C9,D9) -> 1700 | F9: =Données!H11 -> 42 | G9: =E9*F9 -> 71400 | H9: =Données!G11 -> 0.9 | I9: =E9*H9 -> 1530
B10: P7 | C10: ='S1 - projections'!C14+'S1 - projections'!D14+'S1 - projections'!E14 -> 2455 | D10: =Données!J12 -> 50 | E10: =CEILING(C10,D10) -> 2500 | F10: =Données!H12 -> 54 | G10: =E10*F10 -> 135000 | H10: =Données!G12 -> 0.875 | I10: =E10*H10 -> 2187.5
B11: P8 | C11: ='S1 - projections'!C15+'S1 - projections'!D15+'S1 - projections'!E15 -> 7510 | D11: =Données!J13 -> 10 | E11: =CEILING(C11,D11) -> 7510 | F11: =Données!H13 -> 59 | G11: =E11*F11 -> 443090 | H11: =Données!G13 -> 1.8 | I11: =E11*H11 -> 13518
B12: P9 | C12: ='S1 - projections'!C16+'S1 - projections'!D16+'S1 - projections'!E16 -> 4275 | D12: =Données!J14 -> 10 | E12: =CEILING(C12,D12) -> 4280 | F12: =Données!H14 -> 66 | G12: =E12*F12 -> 282480 | H12: =Données!G14 -> 0.5625 | I12: =E12*H12 -> 2407.5
B13: P10 | C13: ='S1 - projections'!C17+'S1 - projections'!D17+'S1 - projections'!E17 -> 1125 | D13: =Données!J15 -> 10 | E13: =CEILING(C13,D13) -> 1130 | F13: =Données!H15 -> 69 | G13: =E13*F13 -> 77970 | H13: =Données!G15 -> 0.75 | I13: =E13*H13 -> 847.5
B14: P11 | C14: ='S1 - projections'!C18+'S1 - projections'!D18+'S1 - projections'!E18 -> 0 | D14: =Données!J16 -> 100 | E14: =CEILING(C14,D14) -> 0 | F14: =Données!H16 -> 22 | G14: =E14*F14 -> 0 | H14: =Données!G16 -> 0.675 | I14: =E14*H14 -> 0
B15: P12 | C15: ='S1 - projections'!C19+'S1 - projections'!D19+'S1 - projections'!E19 -> 0 | D15: =Données!J17 -> 10 | E15: =CEILING(C15,D15) -> 0 | F15: =Données!H17 -> 43 | G15: =E15*F15 -> 0 | H15: =Données!G17 -> 1.75 | I15: =E15*H15 -> 0
B16: P13 | C16: ='S1 - projections'!C20+'S1 - projections'!D20+'S1 - projections'!E20 -> 0 | D16: =Données!J18 -> 10 | E16: =CEILING(C16,D16) -> 0 | F16: =Données!H18 -> 65 | G16: =E16*F16 -> 0 | H16: =Données!G18 -> 1.25 | I16: =E16*H16 -> 0
G22: =SUM(G4:G16) -> 1453427.5 | I22: =SUM(I4:I6) -> 4837.5 | J22: volume total
I23: =ROUNDDOWN(I22/M4,0) -> 32 | J23: Nombre de voyage de 150 m3 en FTL
H24: volume chargé: | I24: =I23*M4 -> 4800
H25: reste | I25: =I22-I24 -> 37.5 | J25: m3
H26: Voyage 100 m3 | I26: =I25/M7 -> 0.375
B28: Coût de la commande 1= | G28: =G22 -> 1453427.5
B29: +frais de transport = le plus petit montant | G29: =MIN(Q4,Q6) -> 27959.375
B30: Total: | G30: =SUM(G28:G29) -> 1481386.9
B33: Note: Taxes à recevoir à traiter plus tard

Sheet S3 - IMMO
A1: Évaluation du bâtiment | C1: Choix: | D1: Acheter | E1: Louer
H2: Volume d'étalage = | N2: Caisses enregistreuses: | V2: Cafétéria:
A3: Magasin et Entrepôt | E3: =K23 -> 22717.048 | H3: Produits | I3: Votre choix: Ventes en unité | J3: Volume unitaire (M3) | K3: Volume total (M3) | N3: ='S1 - projections'!D44 -> 90348.321 | O3: Nombre d'unité vendues totales (en fct de votre choix) | W3: m de hauteur
A4: Espace pour les caisses enregistreuses | E4: =N9 -> 175 | H4: P1 | I4: ='S1 - projections'!AR8+'S1 - projections'!AS8+'S1 - projections'!AT8 -> 10936.852 | J4: =Données!G6 -> 0.18 | K4: =I4*J4 -> 1968.6334 | N4: =1000*13 -> 13000 | O4: capacité des caisses enregistreuses en nombre d'unités par trimestre
A5: Espace de cafétéria pour les employés (60% des employés) | E5: =V14 -> 185.75907 | H5: P2 | I5: ='S1 - projections'!AR9+'S1 - projections'!AS9+'S1 - projections'!AT9 -> 12817.113 | J5: =Données!G7 -> 0.225 | K5: =I5*J5 -> 2883.8505 | N5: =CEILING(N3/N4,1) -> 7 | O5: caisses enregistreuses nécessaires (plafond 1) | U5: Gestionnaire | V5: 1
A6: Espace de bureaux pour vous et certains employés | E6: =W39 -> 192 | H6: P3 | I6: ='S1 - projections'!AR10+'S1 - projections'!AS10+'S1 - projections'!AT10 -> 7573.274 | J6: =Données!G8 -> 0.675 | K6: =I6*J6 -> 5111.96 | N6: 5 | O6: m2 par caisse enregistreuse | U6: Caissier | V6: 7 | X6: (en lien avec le nombre de caisse, non-arrondi)
H7: P4 | I7: ='S1 - projections'!AR11+'S1 - projections'!AS11+'S1 - projections'!AT11 -> 5975.0521 | J7: =Données!G9 -> 0.5 | K7: =I7*J7 -> 2987.526 | N7: =N5*N6 -> 35 | O7: m2 pour le total des caisses enregistreuses | U7: Comptable-gestionnaire | V7: =N3/(W7*K18) -> 2.5740262 | W7: 2700 | X7: (capacité X produits/semaine)
A8: Volume total du bâtiment = | E8: =SUM(E3:E6) -> 23269.807 | F8: m3 | H8: P5 | I8: ='S1 - projections'!AR12+'S1 - projections'!AS12+'S1 - projections'!AT12 -> 9923.6004 | J8: =Données!G10 -> 0.75 | K8: =I8*J8 -> 7442.7003 | N8: 5 | O8: m de hauteur | U8: Vendeur | V8: =N3/(W8*K18) -> 6.9498709 | W8: 1000 | X8: (capacité X produits/semaine)
H9: P6 | I9: ='S1 - projections'!AR13+'S1 - projections'!AS13+'S1 - projections'!AT13 -> 3426.2536 | J9: =Données!G11 -> 0.9 | K9: =I9*J9 -> 3083.6283 | N9: =N7*N8 -> 175 | O9: m3 pour les caisses enregistreuses | U9: Manutentionnaire | V9: =3+(3000-2652)/3000 -> 3.116 | X9: (capacité X m3 de marchandises/semaine)
H10: P7 | I10: ='S1 - projections'!AR14+'S1 - projections'!AS14+'S1 - projections'!AT14 -> 5128.9345 | J10: =Données!G12 -> 0.875 | K10: =I10*J10 -> 4487.8177 | U10: Concierge | W10: =E8 -> 23269.807 | X10: (1 pour 12000 m3) ne pas automatiser
H11: P8 | I11: ='S1 - projections'!AR15+'S1 - projections'!AS15+'S1 - projections'!AT15 -> 15689.735 | J11: =Données!G13 -> 1.8 | K11: =I11*J11 -> 28241.522 | U11: Total des employés: | V11: =SUM(V5:V9) -> 20.639897 | W11: ajouter le nombre de concierges à la main
H12: P9 | I12: ='S1 - projections'!AR16+'S1 - projections'!AS16+'S1 - projections'!AT16 -> 8931.2404 | J12: =Données!G14 -> 0.5625 | K12: =I12*J12 -> 5023.8227 | U12: 0.6 | V12: =V11*U12 -> 12.383938 | W12: (60% des employés)
H13: P10 | I13: ='S1 - projections'!AR17+'S1 - projections'!AS17+'S1 - projections'!AT17 -> 2350.3264 | J13: =Données!G15 -> 0.75 | K13: =I13*J13 -> 1762.7448 | T13: m2/employé | U13: 5 | V13: =V12*U13 -> 61.919691 | W13: M2 total pour les 60% employé
H14: P11 | I14: ='S1 - projections'!AR18+'S1 - projections'!AS18+'S1 - projections'!AT18 -> 1463.6694 | J14: =Données!G16 -> 0.675 | K14: =I14*J14 -> 987.97682 | T14: H | U14: 3 | V14: =V13*U14 -> 185.75907 | W14: M3 (ajout de la hauteur désirée)
H15: P12 | I15: ='S1 - projections'!AR19+'S1 - projections'!AS19+'S1 - projections'!AT19 -> 4365.7724 | J15: =Données!G17 -> 1.75 | K15: =I15*J15 -> 7640.1017
H16: P13 | I16: ='S1 - projections'!AR20+'S1 - projections'!AS20+'S1 - projections'!AT20 -> 1766.4975 | J16: =Données!G18 -> 1.25 | K16: =I16*J16 -> 2208.1219
A17: Achat versus Location du bâtiment | J17: Volume total (étalage) | K17: =SUM(K4:K16) -> 73830.406 | L17: M3 | U17: Volume total en M3 | V17: =N3 -> 90348.321 | W17: Estimation chariots | Z17: (si je prends seulement des chariots élévateurs)
B18: Location | D18: Achat | K18: 13 | L18: semaine par trimestre | U18: Équipement | V18: Coût | W18: Capacité mensuelle M3 de manutention | X18: Capacité trimestrielle M3 de manutention | Y18: Nombre d'équipement | Z18: Volume traité (M3) | AA18: Coût totaux
A19: Location | B19: 1.35 | C19: /m3 | D19: 75 | E19: /m3 | K19: =K17/K18 -> 5679.262 | L19: M3 par semaine | U19: Petit diable | V19: 200 | W19: 1000 | X19: =W19*3 -> 3000 | Y19: 1 | Z19: =X19*Y19 -> 3000 | AA19: =V19*Y19 -> 200 | AB19: Obligatoire pour les petits colis
A20: Amélioration loc. | B20: 15 | C20: /m3 | D20: = | E20: Bâtiment | K20: 2 | L20: semaine d'inventaire | U20: Transpalette | V20: 2200 | W20: 5000 | X20: =W20*3 -> 15000 | Z20: =X20*Y20 -> 0 | AA20: =V20*Y20 -> 0
K21: =K19*2 -> 11358.524 | L21: M3 de marchandise à placer | U21: Chariot élévateur électrique | V21: 11500 | W21: 10000 | X21: =W21*3 -> 30000 | Y21: 3 | Z21: =X21*Y21 -> 90000 | AA21: =V21*Y21 -> 34500 | AB21: Obligatoire si entrepôt supérieur à 5 m de hauteur
K22: 2 | L22: doubler pour espace de circulation | Y22: Total = | Z22: =SUM(Z19:Z21) -> 93000
D23: =SUM(D24:D25) -> 1745235.5 | E23: Total | K23: =K21*2 -> 22717.048 | L23: m3 volume du magasin entrepôt | V23: Nombre: | Y23: Écart besoin | Z23: =Z22-V17 -> 2651.6789
A24: Loyer | B24: =B19*E8 -> 31414.24 | C24: /mois | D24: =(D19*E8)*85% -> 1483450.2 | E24: Terrain | K24: 5 | L24: mètre en hauteur | U24: Besoin en manutentionnaire: | V24: =Y21+(V17-Z22)/X20 -> 2.8232214
A25: Amélioration loc | B25: =ROUND((B20*E8),-3) -> 349000 | D25: =(D19*E8)*15% -> 261785.33 | E25: Bâtiment | K25: =K23/K24 -> 4543.4096 | L25: Surface d'étalages (en m2)
H28: Votre choix provient de ce tableau que vous avez calculé dans la feuille Excel des estimés de ventes!
A29: Module de caisses enregistreuses ( 4500$/module) | C29: =4500*N5 -> 31500 | E29: bureau vendeur | F29: =ROUND(7/2,0) -> 4
A30: Bureaux - Administration (955$/bureau) | C30: =CEILING((955*4),100) -> 3900
A31: Bureaux - vendeur ( 900$/ 2 bureaux) | C31: =CEILING((900*4),100) -> 3600
A32: Ameublement cafétéria (350$ / 4 employés) | C32: =CEILING((V12/4)*350,1) -> 1084 | V32: Espace bureau
A33: Étalage magasin (120$/ 10 m3) | C33: =(K21*30%)/10*120 -> 40890.687 | V33: Gestionnaire | W33: =V5 -> 1
A34: Étalage entrepôt (70$/ 10 m3) | C34: =(K21*70%)/10*70 -> 55656.768 | V34: Comptable-gestionnaire | W34: =V7 -> 2.5740262
A35: Équipement informatique (5000$/bureaux) | C35: =5000*(F29+W36) -> 40000 | V35: Total = | W35: =SUM(W33:W34) -> 3.5740262
A36: Équipement de manutention (voir tableau + haut) | C36: =AA21+AA19 -> 34700 | V36: arrondi.sup | W36: =ROUNDUP(W35,0) -> 4 | X36: bureau
A37: Équipement de cuisine (1000$ / 5 employés) | C37: =CEILING(V11/5,1)*1000 -> 5000 | W37: 16 | X37: m2
V38: Hauteur | W38: 3
V39: Volume M3 pour espace bureau | W39: =(W36*W37)*W38 -> 192

Sheet S4 - Montage financier
B1: Actif | E1: Passif | G1: Calculs des passifs: | K1: Actif | N1: Passif | P1: Calculs des passifs:
A2: =0.05+0.09975 -> 0.14975 | B2: Taxes à recevoir | C2: =C3*J2 -> 217650.77 | D2: =CEILING(((C2-0)*Q2)+((C3-D3)*R2)+(0*S2),1000) -> 670000 | E2: Marge de crédit | J2: =0.05+0.09975 -> 0.14975 | K2: Taxes à recevoir | L2: =C2 -> 217650.77 | M2: =D2 -> 670000 | N2: Marge de crédit | P2: 0.11 | Q2: 1 | R2: 0.75 | S2: 0.7 | T2: plafond (1000$)
B3: Stock de marchandises | C3: ='S2 - Inventaire départ'!G28 -> 1453427.5 | D3: ='S2 - Inventaire départ'!G30*(1+J2)*P3 -> 851612.28 | E3: Comptes fournisseurs | K3: Stock de marchandises | L3: =C3 -> 1453427.5 | M3: =D3 -> 851612.28 | N3: Comptes fournisseurs | P3: 0.5
B4: Charges payées d'avance | C4: =25000 -> 25000 | D4: {=SUM(C11+C9:C10)*70%} -> 59290 | E4: Hypothèque | K4: Charges payées d'avance | L4: =C4 -> 25000 | M4: =D4 -> 59290 | N4: Hypothèque | P4: 0.06 | Q4: 0.7 | R4: plafond (1000$)
B5: Frais d'incorporation | C5: =6500 -> 6500 | D5: =18498+133509 -> 152007 | E5: Capital de risque | K5: Frais d'incorporation | L5: =C5 -> 6500 | M5: =D5 -> 152007 | N5: Capital de risque | P5: 0.1
B6: Améliorations locatives | C6: ='S3 - IMMO'!B25 -> 349000 | K6: Terrain | L6: ='S3 - IMMO'!D24 -> 1483450.2
B7: Caisses enregistreuses | C7: ='S3 - IMMO'!C29 -> 31500 | K7: Bâtiment | L7: ='S3 - IMMO'!D25 -> 261785.33
B8: Ameublement | C8: =SUM('S3 - IMMO'!C30:C34) -> 105131.45 | K8: Caisses enregistreuses | L8: =C7 -> 31500
B9: Équipement informatique | C9: ='S3 - IMMO'!C35 -> 40000 | E9: Capitaux propres | K9: Ameublement | L9: =C8 -> 105131.45
B10: Équipement de manutention | C10: ='S3 - IMMO'!C36 -> 34700 | D10: =450000 -> 450000 | E10: Capital-actions | K10: Équipement informatique | L10: =C9 -> 40000 | N10: Capitaux propres
B11: Équipement de cuisine | C11: ='S3 - IMMO'!C37 -> 5000 | D11: =85000 -> 85000 | E11: Subvention | K11: Équipement de manutention | L11: =C10 -> 34700 | M11: =D10 -> 450000 | N11: Capital-actions
K12: Équipement de cuisine | L12: =C11 -> 5000 | N12: Subvention
B13: Total des actifs: | C13: =SUM(C2:C11) -> 2267909.7 | D13: =SUM(D2:D11) -> 2267909.3 | E13: :Total des passifs et des capitaux propres
K14: Total des actifs: | L14: =SUM(L2:L12) -> 3664145.3 | M14: =SUM(M2:M12) -> 2182909.3 | N14: :Total des passifs et des capitaux propres
C15: écart: | D15: =C13-D13 -> 0.44298388
L16: écart: | M16: =L14-M14 -> 1481236
A17: Faites votre choix final et inscrire les informations dans votre bilan de démarrage sur Acomba
A18: Dans les soldes d'ouverture de chacun de vos comptes | J18: Faire votre bon de commande 1 (énoncé de travail)
J19: Voir modèle disponible sur Léa
H29: Marge de crédit:

Sheet IMPORTANT

Sheet S5 -Outil - Ventes
C3: Analyse des ventes
D4: VOIR DOC. LÉA | H4: E *prix de vente + F*50%*Prix de vente | I4: =(C-E-F) | J4: H * Prix coûtant | K4: Analyse complémentaire (ventes perdue)
B5: Produits | C5: Quantités commandées | D5: Ventes potentielles | E5: Ventes réelles en unités | F5: Inventaire de début | G5: Ventes produit saisonniers en unités | H5: Ventes totales (TRIM 1) en $ (sans les taxes à payer) | I5: Inventaire de fin (en unités) | J5: Inventaire de fin (en $) | K5: Produits | L5: Écart (en unité) | M5: Écart (en $) | N5: Besoins commande 2 | O5: Volume unitaire (M3) | P5: Volume total achété (M3)
B6: P1 | C6: ='S2 - Inventaire départ'!E4 -> 5250 | D6: 5385 | E6: =MIN(C6:D6) -> 5250 | F6: ='Fournisseur 1'!B10 -> 5300 | H6: =(E6*Données!I6)+(G6*50%)*Données!I6 -> 57067.5 | I6: =C6-E6-G6 -> 0 | J6: =I6*Données!H6 -> 0 | K6: =B6 -> P1 | L6: =IF(D6>E6,D6-E6,0) -> 135 | M6: =L6*Données!I6 -> 1467.45 | O6: ='S3 - IMMO'!J4 -> 0.18 | P6: =(E6+N6)*O6 -> 945
B7: P2 | C7: ='S2 - Inventaire départ'!E5 -> 6200 | D7: 6270 | E7: =MIN(C7:D7) -> 6200 | F7: ='Fournisseur 1'!B11 -> 6200 | H7: =(E7*Données!I7)+(G7*50%)*Données!I7 -> 134788 | I7: =C7-E7-G7 -> 0 | J7: =I7*Données!H7 -> 0 | K7: =B7 -> P2 | L7: =IF(D7>E7,D7-E7,0) -> 70 | M7: =L7*Données!I7 -> 1521.8 | O7: ='S3 - IMMO'!J5 -> 0.225 | P7: =(E7+N7)*O7 -> 1395
B8: P3 | C8: ='S2 - Inventaire départ'!E6 -> 3700 | D8: 3477 | E8: =MIN(C8:D8) -> 3477 | F8: ='Fournisseur 1'!B12 -> 3700 | H8: =(E8*Données!I8)+(G8*50%)*Données!I8 -> 121764.54 | I8: =C8-E8-G8 -> 223 | J8: =I8*Données!H8 -> 4460 | K8: =B8 -> P3 | L8: =IF(D8>E8,D8-E8,0) -> 0 | M8: =L8*Données!I8 -> 0 | O8: ='S3 - IMMO'!J6 -> 0.675 | P8: =(E8+N8)*O8 -> 2346.975
B9: P4 | C9: ='S2 - Inventaire départ'!E7 -> 2900 | D9: 2923 | E9: =MIN(C9:D9) -> 2900 | F9: ='Fournisseur 1'!B13 -> 2900 | H9: =(E9*Données!I9)+(G9*50%)*Données!I9 -> 122554 | I9: =C9-E9-G9 -> 0 | J9: =I9*Données!H9 -> 0 | K9: =B9 -> P4 | L9: =IF(D9>E9,D9-E9,0) -> 23 | M9: =L9*Données!I9 -> 971.98 | O9: ='S3 - IMMO'!J7 -> 0.5 | P9: =(E9+N9)*O9 -> 1450
B10: P5 | C10: ='S2 - Inventaire départ'!E8 -> 4750 | D10: 4754 | E10: =MIN(C10:D10) -> 4750 | F10: ='Fournisseur 1'!B14 -> 4800 | H10: =(E10*Données!I10)+(G10*50%)*Données!I10 -> 281057.5 | I10: =C10-E10-G10 -> 0 | J10: =I10*Données!H10 -> 0 | K10: =B10 -> P5 | L10: =IF(D10>E10,D10-E10,0) -> 4 | M10: =L10*Données!I10 -> 236.68 | O10: ='S3 - IMMO'!J8 -> 0.75 | P10: =(E10+N10)*O10 -> 3562.5
B11: P6 | C11: ='S2 - Inventaire départ'!E9 -> 1700 | D11: 1621 | E11: =MIN(C11:D11) -> 1621 | F11: ='Fournisseur 1'!B15 -> 1700 | H11: =(E11*Données!I11)+(G11*50%)*Données!I11 -> 103744 | I11: =C11-E11-G11 -> 79 | J11: =I11*Données!H11 -> 3318 | K11: =B11 -> P6 | L11: =IF(D11>E11,D11-E11,0) -> 0 | M11: =L11*Données!I11 -> 0 | O11: ='S3 - IMMO'!J9 -> 0.9 | P11: =(E11+N11)*O11 -> 1458.9
